Начало работы скрипта
sdk создано
Задаём датасет
Начинаем тюнинг
Traceback (most recent call last):
  File "/home/ss/lora/Order_recognition/training/tune_yandex.py", line 49, in <module>
    main()
  File "/home/ss/lora/Order_recognition/training/tune_yandex.py", line 33, in main
    tuned_model = base_model.tune(train_dataset, name=str(uuid.uuid4()))
                  ^^^^^^^^^^^^^^^^^^^^^^^^^^^^^^^^^^^^^^^^^^^^^^^^^^^^^^
  File "/home/ss/lora/Order_recognition/.venv/lib/python3.11/site-packages/yandex_cloud_ml_sdk/_models/completions/model.py", line 450, in tune
    return self.__tune(
           ^^^^^^^^^^^^
  File "/home/ss/lora/Order_recognition/.venv/lib/python3.11/site-packages/yandex_cloud_ml_sdk/_utils/sync.py", line 61, in wrapped
    return run_sync_impl(inner, self._sdk)
           ^^^^^^^^^^^^^^^^^^^^^^^^^^^^^^^
  File "/home/ss/lora/Order_recognition/.venv/lib/python3.11/site-packages/yandex_cloud_ml_sdk/_utils/sync.py", line 38, in run_sync_impl
    result: T = _runner_map[key].run(coro)
                ^^^^^^^^^^^^^^^^^^^^^^^^^^
  File "/home/ss/lora/Order_recognition/.venv/lib/python3.11/site-packages/yandex_cloud_ml_sdk/_utils/sync.py", line 26, in run
    return fut.result(None)
           ^^^^^^^^^^^^^^^^
  File "/usr/lib/python3.11/concurrent/futures/_base.py", line 456, in result
    return self.__get_result()
           ^^^^^^^^^^^^^^^^^^^
  File "/usr/lib/python3.11/concurrent/futures/_base.py", line 401, in __get_result
    raise self._exception
  File "/home/ss/lora/Order_recognition/.venv/lib/python3.11/site-packages/yandex_cloud_ml_sdk/_types/model.py", line 125, in _tune
    result = await operation._wait(
             ^^^^^^^^^^^^^^^^^^^^^^
  File "/home/ss/lora/Order_recognition/.venv/lib/python3.11/site-packages/yandex_cloud_ml_sdk/_types/operation.py", line 110, in _wait
    return await self._get_result(timeout=timeout)
           ^^^^^^^^^^^^^^^^^^^^^^^^^^^^^^^^^^^^^^^
  File "/home/ss/lora/Order_recognition/.venv/lib/python3.11/site-packages/yandex_cloud_ml_sdk/_tuning/tuning_task.py", line 217, in _get_result
    raise RunError.from_proro_status(status.error, operation_id=self.id)
yandex_cloud_ml_sdk._exceptions.RunError: Operation ftngnbi30h5n96cauflp failed with message: Quota fomo.tunings.count.per.hour exhausted for cloud b1gtgs2jj8r5rt3bomk5 (code 8)

WARNING: All log messages before absl::InitializeLog() is called are written to STDERR
E0000 00:00:1739517558.230937  127836 init.cc:232] grpc_wait_for_shutdown_with_timeout() timed out.
